Traceback (most recent call last):
  File "/usr/lib/python3/dist-packages/serial/serialposix.py", line 322, in open
    self.fd = os.open(self.portstr, os.O_RDWR | os.O_NOCTTY | os.O_NONBLOCK)
              ^^^^^^^^^^^^^^^^^^^^^^^^^^^^^^^^^^^^^^^^^^^^^^^^^^^^^^^^^^^^^^
FileNotFoundError: [Errno 2] No such file or directory: '/dev/ttyACM0'

During handling of the above exception, another exception occurred:

Traceback (most recent call last):
  File "/home/henry/Documents/ac-dev/testing/console/main.py", line 44, in <module>
    curses.wrapper(lambda stdscr: asyncio.run(main(stdscr)))
  File "/usr/lib/python3.12/curses/__init__.py", line 94, in wrapper
    return func(stdscr, *args, **kwds)
           ^^^^^^^^^^^^^^^^^^^^^^^^^^^
  File "/home/henry/Documents/ac-dev/testing/console/main.py", line 44, in <lambda>
    curses.wrapper(lambda stdscr: asyncio.run(main(stdscr)))
                                  ^^^^^^^^^^^^^^^^^^^^^^^^^
  File "/usr/lib/python3.12/asyncio/runners.py", line 194, in run
    return runner.run(main)
           ^^^^^^^^^^^^^^^^
  File "/usr/lib/python3.12/asyncio/runners.py", line 118, in run
    return self._loop.run_until_complete(task)
           ^^^^^^^^^^^^^^^^^^^^^^^^^^^^^^^^^^^
  File "/usr/lib/python3.12/asyncio/base_events.py", line 687, in run_until_complete
    return future.result()
           ^^^^^^^^^^^^^^^
  File "/home/henry/Documents/ac-dev/testing/console/main.py", line 41, in main
    await asyncio.gather(*tasks)
  File "/home/henry/Documents/ac-dev/testing/console/protocol.py", line 38, in serial_task
    transport, protocol = await serial_asyncio.create_serial_connection(
                          ^^^^^^^^^^^^^^^^^^^^^^^^^^^^^^^^^^^^^^^^^^^^^^
  File "/usr/lib/python3/dist-packages/serial_asyncio/__init__.py", line 448, in create_serial_connection
    serial_instance = serial.serial_for_url(*args, **kwargs)
                      ^^^^^^^^^^^^^^^^^^^^^^^^^^^^^^^^^^^^^^
  File "/usr/lib/python3/dist-packages/serial/__init__.py", line 90, in serial_for_url
    instance.open()
  File "/usr/lib/python3/dist-packages/serial/serialposix.py", line 325, in open
    raise SerialException(msg.errno, "could not open port {}: {}".format(self._port, msg))
serial.serialutil.SerialException: [Errno 2] could not open port /dev/ttyACM0: [Errno 2] No such file or directory: '/dev/ttyACM0'
